Workbook

Sheet Presupuesto
A1: Presupuesto estimado a precios de mercado - Jardín sustentable EDS 40000 Tongoy Barrio Industrial
A2: Cantidades del diseño Rev. A (L-01). Precios unitarios netos desde la hoja Precios. No usa el análisis económico del Manual COPEC.
A4: Capítulo | B4: Partida | C4: Unidad | D4: Cantidad | E4: Clave precio | F4: P.U. bajo | G4: P.U. típico | H4: P.U. alto | I4: Total bajo | J4: Total típico | K4: Total alto
A5: 1 Obras preliminares | B5: Instalación de faena (bodega, baño químico, cierre y señalización en EDS) | C5: gl | D5: 1 | E5: faena | F5: =INDEX(Precios!$D$5:$D$56,MATCH($E5,Precios!$A$5:$A$56,0)) -> 400000 | G5: =INDEX(Precios!$E$5:$E$56,MATCH($E5,Precios!$A$5:$A$56,0)) -> 700000 | H5: =INDEX(Precios!$F$5:$F$56,MATCH($E5,Precios!$A$5:$A$56,0)) -> 1200000 | I5: =$D5*F5 -> 400000 | J5: =$D5*G5 -> 700000 | K5: =$D5*H5 -> 1200000
A6: 1 Obras preliminares | B6: Prevención de riesgos en estación de combustible (prevencionista part-time, EPP, permisos) | C6: gl | D6: 1 | E6: hse | F6: =INDEX(Precios!$D$5:$D$56,MATCH($E6,Precios!$A$5:$A$56,0)) -> 300000 | G6: =INDEX(Precios!$E$5:$E$56,MATCH($E6,Precios!$A$5:$A$56,0)) -> 600000 | H6: =INDEX(Precios!$F$5:$F$56,MATCH($E6,Precios!$A$5:$A$56,0)) -> 1200000 | I6: =$D6*F6 -> 300000 | J6: =$D6*G6 -> 600000 | K6: =$D6*H6 -> 1200000
A7: 1 Obras preliminares | B7: Análisis de suelo y agua (salinidad, pH, MO, textura; agua Lavamax) | C7: gl | D7: 1 | E7: analisis_suelo_agua | F7: =INDEX(Precios!$D$5:$D$56,MATCH($E7,Precios!$A$5:$A$56,0)) -> 150000 | G7: =INDEX(Precios!$E$5:$E$56,MATCH($E7,Precios!$A$5:$A$56,0)) -> 300000 | H7: =INDEX(Precios!$F$5:$F$56,MATCH($E7,Precios!$A$5:$A$56,0)) -> 500000 | I7: =$D7*F7 -> 150000 | J7: =$D7*G7 -> 300000 | K7: =$D7*H7 -> 500000
A8: 1 Obras preliminares | B8: Descompactación / escarificado de suelo 20-30 cm | C8: m² | D8: 2246.98 | E8: descompactacion | F8: =INDEX(Precios!$D$5:$D$56,MATCH($E8,Precios!$A$5:$A$56,0)) -> 600 | G8: =INDEX(Precios!$E$5:$E$56,MATCH($E8,Precios!$A$5:$A$56,0)) -> 1100 | H8: =INDEX(Precios!$F$5:$F$56,MATCH($E8,Precios!$A$5:$A$56,0)) -> 2000 | I8: =$D8*F8 -> 1348188 | J8: =$D8*G8 -> 2471678 | K8: =$D8*H8 -> 4493960
A9: 1 Obras preliminares | B9: Traslado diario de cuadrilla La Serena/Coquimbo - Tongoy | C9: día | D9: 40 | E9: traslado_dia | F9: =INDEX(Precios!$D$5:$D$56,MATCH($E9,Precios!$A$5:$A$56,0)) -> 20000 | G9: =INDEX(Precios!$E$5:$E$56,MATCH($E9,Precios!$A$5:$A$56,0)) -> 30000 | H9: =INDEX(Precios!$F$5:$F$56,MATCH($E9,Precios!$A$5:$A$56,0)) -> 45000 | I9: =$D9*F9 -> 800000 | J9: =$D9*G9 -> 1200000 | K9: =$D9*H9 -> 1800000
A10: 2 Suelo y plantación | B10: Compost maduro puesto en obra (50 % del volumen de hoyaduras) | C10: m³ | D10: 27.49 | E10: compost_m3 | F10: =INDEX(Precios!$D$5:$D$56,MATCH($E10,Precios!$A$5:$A$56,0)) -> 35000 | G10: =INDEX(Precios!$E$5:$E$56,MATCH($E10,Precios!$A$5:$A$56,0)) -> 50000 | H10: =INDEX(Precios!$F$5:$F$56,MATCH($E10,Precios!$A$5:$A$56,0)) -> 95000 | I10: =$D10*F10 -> 962150 | J10: =$D10*G10 -> 1374500 | K10: =$D10*H10 -> 2611550
A11: 2 Suelo y plantación | B11: Retiro de excedentes a botadero autorizado | C11: m³ | D11: 34.36 | E11: botadero_m3 | F11: =INDEX(Precios!$D$5:$D$56,MATCH($E11,Precios!$A$5:$A$56,0)) -> 13000 | G11: =INDEX(Precios!$E$5:$E$56,MATCH($E11,Precios!$A$5:$A$56,0)) -> 21000 | H11: =INDEX(Precios!$F$5:$F$56,MATCH($E11,Precios!$A$5:$A$56,0)) -> 32000 | I11: =$D11*F11 -> 446680 | J11: =$D11*G11 -> 721560 | K11: =$D11*H11 -> 1099520
A12: 2 Suelo y plantación | B12: Plantación árbol (hoyadura 40x60, mezcla, tutor, taza, riego asentamiento) | C12: u | D12: 29 | E12: mo_arbol | F12: =INDEX(Precios!$D$5:$D$56,MATCH($E12,Precios!$A$5:$A$56,0)) -> 4000 | G12: =INDEX(Precios!$E$5:$E$56,MATCH($E12,Precios!$A$5:$A$56,0)) -> 6500 | H12: =INDEX(Precios!$F$5:$F$56,MATCH($E12,Precios!$A$5:$A$56,0)) -> 11000 | I12: =$D12*F12 -> 116000 | J12: =$D12*G12 -> 188500 | K12: =$D12*H12 -> 319000
A13: 2 Suelo y plantación | B13: Plantación arbusto (hoyadura 30x40, mezcla, plantación) | C13: u | D13: 783 | E13: mo_arbusto | F13: =INDEX(Precios!$D$5:$D$56,MATCH($E13,Precios!$A$5:$A$56,0)) -> 1500 | G13: =INDEX(Precios!$E$5:$E$56,MATCH($E13,Precios!$A$5:$A$56,0)) -> 2300 | H13: =INDEX(Precios!$F$5:$F$56,MATCH($E13,Precios!$A$5:$A$56,0)) -> 3400 | I13: =$D13*F13 -> 1174500 | J13: =$D13*G13 -> 1800900 | K13: =$D13*H13 -> 2662200
A14: 2 Suelo y plantación | B14: Plantación herbácea / cubresuelo (hoyadura 30x30) | C14: u | D14: 889 | E14: mo_herbacea | F14: =INDEX(Precios!$D$5:$D$56,MATCH($E14,Precios!$A$5:$A$56,0)) -> 1000 | G14: =INDEX(Precios!$E$5:$E$56,MATCH($E14,Precios!$A$5:$A$56,0)) -> 1600 | H14: =INDEX(Precios!$F$5:$F$56,MATCH($E14,Precios!$A$5:$A$56,0)) -> 2600 | I14: =$D14*F14 -> 889000 | J14: =$D14*G14 -> 1422400 | K14: =$D14*H14 -> 2311400
A15: 2 Suelo y plantación | B15: Tutor de madera y amarras para árboles | C15: u | D15: 29 | E15: tutor | F15: =INDEX(Precios!$D$5:$D$56,MATCH($E15,Precios!$A$5:$A$56,0)) -> 2185 | G15: =INDEX(Precios!$E$5:$E$56,MATCH($E15,Precios!$A$5:$A$56,0)) -> 3193 | H15: =INDEX(Precios!$F$5:$F$56,MATCH($E15,Precios!$A$5:$A$56,0)) -> 5042 | I15: =$D15*F15 -> 63365 | J15: =$D15*G15 -> 92597 | K15: =$D15*H15 -> 146218
A16: 3 Suministro de plantas | B16: Molle (Schinus latifolius) | C16: u | D16: 2 | E16: planta_SL | F16: =INDEX(Precios!$D$5:$D$56,MATCH($E16,Precios!$A$5:$A$56,0)) -> 5462 | G16: =INDEX(Precios!$E$5:$E$56,MATCH($E16,Precios!$A$5:$A$56,0)) -> 7563 | H16: =INDEX(Precios!$F$5:$F$56,MATCH($E16,Precios!$A$5:$A$56,0)) -> 10924 | I16: =$D16*F16 -> 10924 | J16: =$D16*G16 -> 15126 | K16: =$D16*H16 -> 21848
... A55: 6 Mobiliario y educación ambiental | B55: Panel interpretativo con QR, instalado | C55: u | D55: 3 | E55: panel | F55: =INDEX(Precios!$D$5:$D$56,MATCH($E55,Precios!$A$5:$A$56,0)) -> 350000 | G55: =INDEX(Precios!$E$5:$E$56,MATCH($E55,Precios!$A$5:$A$56,0)) -> 650000 | H55: =INDEX(Precios!$F$5:$F$56,MATCH($E55,Precios!$A$5:$A$56,0)) -> 1200000 | I55: =$D55*F55 -> 1050000 | J55: =$D55*G55 -> 1950000 | K55: =$D55*H55 -> 3600000
A56: 7 Reposición e imprevistos | B56: Reposición de plantas por garantía de prendimiento (% del suministro de plantas) | C56: % | I56: =SUM(I16:I37)*Supuestos!B9 -> 148351 | J56: =SUM(J16:J37)*Supuestos!C9 -> 327206.32 | K56: =SUM(K16:K37)*Supuestos!D9 -> 717524.7
A57: 7 Reposición e imprevistos | B57: Imprevistos (calcreta, interferencias, ajustes de terreno) | C57: % | I57: =SUM(I5:I56)*Supuestos!B8 -> 732103.08 | J57: =SUM(J5:J56)*Supuestos!C8 -> 1878614.9 | K57: =SUM(K5:K56)*Supuestos!D8 -> 4821078.8
B59: RESUMEN POR CAPÍTULO
B60: 1 Obras preliminares | I60: =SUMIF($A$5:$A$57,$B60,I$5:I$57) -> 2998188 | J60: =SUMIF($A$5:$A$57,$B60,J$5:J$57) -> 5271678 | K60: =SUMIF($A$5:$A$57,$B60,K$5:K$57) -> 9193960
B61: 2 Suelo y plantación | I61: =SUMIF($A$5:$A$57,$B61,I$5:I$57) -> 3651695 | J61: =SUMIF($A$5:$A$57,$B61,J$5:J$57) -> 5600457 | K61: =SUMIF($A$5:$A$57,$B61,K$5:K$57) -> 9149888
B62: 3 Suministro de plantas | I62: =SUMIF($A$5:$A$57,$B62,I$5:I$57) -> 3727020 | J62: =SUMIF($A$5:$A$57,$B62,J$5:J$57) -> 5874376 | K62: =SUMIF($A$5:$A$57,$B62,K$5:K$57) -> 8875247
B63: 4 Cobertura mineral | I63: =SUMIF($A$5:$A$57,$B63,I$5:I$57) -> 8617090 | J63: =SUMIF($A$5:$A$57,$B63,J$5:J$57) -> 11414554 | K63: =SUMIF($A$5:$A$57,$B63,K$5:K$57) -> 16739856
B64: 5 Riego tecnificado | I64: =SUMIF($A$5:$A$57,$B64,I$5:I$57) -> 3961091.9 | J64: =SUMIF($A$5:$A$57,$B64,J$5:J$57) -> 6684026.5 | K64: =SUMIF($A$5:$A$57,$B64,K$5:K$57) -> 11187010
B65: 6 Mobiliario y educación ambiental | I65: =SUMIF($A$5:$A$57,$B65,I$5:I$57) -> 1300000 | J65: =SUMIF($A$5:$A$57,$B65,J$5:J$57) -> 2400000 | K65: =SUMIF($A$5:$A$57,$B65,K$5:K$57) -> 4400000
B66: 7 Reposición e imprevistos | I66: =SUMIF($A$5:$A$57,$B66,I$5:I$57) -> 880454.08 | J66: =SUMIF($A$5:$A$57,$B66,J$5:J$57) -> 2205821.2 | K66: =SUMIF($A$5:$A$57,$B66,K$5:K$57) -> 5538603.5
B67: COSTO DIRECTO | I67: =SUM(I60:I66) -> 25135539 | J67: =SUM(J60:J66) -> 39450913 | K67: =SUM(K60:K66) -> 65084564
B68: Gastos generales | I68: =I67*Supuestos!B6 -> 2513553.9 | J68: =J67*Supuestos!C6 -> 4734109.5 | K68: =K67*Supuestos!D6 -> 11064376
B69: Utilidades | I69: =I67*Supuestos!B7 -> 2513553.9 | J69: =J67*Supuestos!C7 -> 5128618.6 | K69: =K67*Supuestos!D7 -> 11715222
B70: TOTAL NETO (sin IVA) | I70: =I67+I68+I69 -> 30162647 | J70: =J67+J68+J69 -> 49313641 | K70: =K67+K68+K69 -> 87864162
B71: IVA | I71: =I70*Supuestos!B10 -> 5730902.9 | J71: =J70*Supuestos!C10 -> 9369591.8 | K71: =K70*Supuestos!D10 -> 16694191
B72: TOTAL CON IVA | I72: =I70+I71 -> 35893550 | J72: =J70+J71 -> 58683233 | K72: =K70+K71 -> 1.0455835e+08
B74: UF/m² neto (superficie plantable) | I74: =I70/Supuestos!B5/Supuestos!B11 -> 0.32621288 | J74: =J70/Supuestos!C5/Supuestos!C11 -> 0.53333332 | K74: =K70/Supuestos!D5/Supuestos!D11 -> 0.95026213
B75: UF/m² neto (superficie bruta) | I75: =I70/Supuestos!B5/Supuestos!B12 -> 0.31421632 | J75: =J70/Supuestos!C5/Supuestos!C12 -> 0.51371986 | K75: =K70/Supuestos!D5/Supuestos!D12 -> 0.91531601
B76: CLP/m² neto (superficie plantable) | I76: =I70/Supuestos!B11 -> 13423.66 | J76: =J70/Supuestos!C11 -> 21946.666 | K76: =K70/Supuestos!D11 -> 39103.287
B77: UF/m² con IVA (superficie plantable) | I77: =I72/Supuestos!B5/Supuestos!B11 -> 0.38819332 | J77: =J72/Supuestos!C5/Supuestos!C11 -> 0.63466666 | K77: =K72/Supuestos!D5/Supuestos!D11 -> 1.1308119
B78: Total neto en UF | I78: =I70/Supuestos!B5 -> 732.99263 | J78: =J70/Supuestos!C5 -> 1198.3874 | K78: =K70/Supuestos!D5 -> 2135.2166
B80: PARTIDAS FUERA DEL TOTAL (agregar según contrato)
B81: Mantención de establecimiento 3 meses (incluye GG+U) | C81: m²·mes | D81: =Supuestos!B11*3 -> 6740.9292 | I81: =$D81*Precios!D56*(1+Supuestos!B6+Supuestos!B7) -> 1213367.2 | J81: =$D81*Precios!E56*(1+Supuestos!C6+Supuestos!C7) -> 2949156.5 | K81: =$D81*Precios!F56*(1+Supuestos!D6+Supuestos!D7) -> 6370178.1
B82: OPCIONAL: rebaje de 10 cm de la superficie si obra civil no entrega la cota (225 m³: excavación + botadero, incluye GG+U) | C82: m³ | D82: 225 | I82: =$D82*(3000+Precios!D11*1.25)*(1+Supuestos!B6+Supuestos!B7) -> 5197500 | J82: =$D82*(5000+Precios!E11*1.25)*(1+Supuestos!C6+Supuestos!C7) -> 8789062.5 | K82: =$D82*(10000+Precios!F11*1.25)*(1+Supuestos!D6+Supuestos!D7) -> 15187500
...

Sheet Supuestos
A1: Supuestos generales del presupuesto
A2: Celdas en azul con fondo amarillo = supuestos editables. Precios NETOS (sin IVA) en CLP. Octubre 2026.
A4: Supuesto | B4: Bajo | C4: Típico | D4: Alto | E4: Nota / fuente
A5: Valor UF (CLP) | B5: 41150 | C5: 41150 | D5: 41150 | E5: UF octubre 2026 (~$41.065 el 1-oct y ~$41.248 el 31-oct; calcular.cl / uf-hoy.com sobre datos del Banco Central)
A6: Gastos generales (% del costo directo) | B6: 0.1 | C6: 0.12 | D6: 0.17 | E6: Rango de mercado de GG+U en contratos de paisajismo en Chile: 20-35 % (licitaciones y cotizaciones)
A7: Utilidades (% del costo directo) | B7: 0.1 | C7: 0.13 | D7: 0.18 | E7: Ídem
A8: Imprevistos (% del costo directo antes de imprevistos) | B8: 0.03 | C8: 0.05 | D8: 0.08 | E8: Calcreta, interferencias con redes, ajustes de terreno
A9: Reposición de plantas por garantía (% del suministro de plantas) | B9: 0.05 | C9: 0.07 | D9: 0.1 | E9: Garantía de prendimiento 5-10 % según viveros y contratistas
A10: IVA | B10: 0.19 | C10: 0.19 | D10: 0.19 | E10: Ley de IVA
A11: Superficie de jardín plantable (m²) | B11: 2246.9764 | C11: 2246.9764 | D11: 2246.9764 | E11: Del diseño L-01 (descuenta losa de estanques, cargadores EV, Lavamax, luminarias)
A12: Superficie de jardín bruta (m²) | B12: 2332.7644 | C12: 2332.7644 | D12: 2332.7644 | E12: Del diseño L-01

Sheet Precios
A1: Precios unitarios de mercado (CLP netos, sin IVA)
A2: Los precios publicados con IVA se convirtieron a neto (÷1,19). Bajo / típico / alto según fuentes de mercado verificadas (ver hoja Fuentes).
A4: Clave | B4: Descripción | C4: Unidad | D4: Bajo | E4: Típico | F4: Alto | G4: Nota
A5: faena | B5: Instalación de faena en EDS en operación | C5: gl | D5: 400000 | E5: 700000 | F5: 1200000 | G5: Estimación: bodega/contenedor + baño químico ~2 meses + cierre y señalización
A6: hse | B6: Prevención de riesgos (prevencionista part-time, EPP, permisos de trabajo) | C6: gl | D6: 300000 | E6: 600000 | F6: 1200000 | G6: Requisito para trabajar en estación de combustible en operación
A7: analisis_suelo_agua | B7: Análisis de laboratorio de suelo (2) y agua (1) | C7: gl | D7: 150000 | E7: 300000 | F7: 500000 | G7: Salinidad, pH, MO, textura; agua reciclada Lavamax
A8: descompactacion | B8: Descompactación/escarificado de suelo 20-30 cm | C8: m² | D8: 600 | E8: 1100 | F8: 2000 | G8: Mezcla mecánico (bandejones) y manual (franjas angostas)
A9: traslado_dia | B9: Traslado diario de cuadrilla La Serena/Coquimbo-Tongoy (vehículo y combustible) | C9: día | D9: 20000 | E9: 30000 | F9: 45000 | G9: ~50 km por tramo
A10: compost_m3 | B10: Compost maduro a granel puesto en obra | C10: m³ | D10: 35000 | E10: 50000 | F10: 95000
A11: botadero_m3 | B11: Carguío, transporte y disposición en botadero autorizado | C11: m³ | D11: 13000 | E11: 21000 | F11: 32000
A12: mo_arbol | B12: Mano de obra plantación árbol 10 L (hoyadura 40x60, tutor, taza, riego) | C12: u | D12: 4000 | E12: 6500 | F12: 11000
A13: mo_arbusto | B13: Mano de obra plantación arbusto (hoyadura 30x40, mezcla con compost) | C13: u | D13: 1500 | E13: 2300 | F13: 3400 | G13: Jornal La Serena ~$31 mil/día (aviso Yapo jun-2026) + leyes sociales; rendimiento con hoyadura del diseño
A14: mo_herbacea | B14: Mano de obra plantación herbácea/cubresuelo (hoyadura 30x30) | C14: u | D14: 1000 | E14: 1600 | F14: 2600 | G14: Jornal La Serena ~$31 mil/día (aviso Yapo jun-2026) + leyes sociales; rendimiento con hoyadura del diseño
A15: tutor | B15: Tutor de madera impregnada + amarras | C15: u | D15: 2185 | E15: 3193 | F15: 5042
A16: planta_SL | B16: Molle (Schinus latifolius), Bolsa 20x30, 1,0-1,3 m | C16: u | D16: 5462 | E16: 7563 | F16: 10924 | G16: Precio vivero al detalle convertido a neto; compras por volumen pueden bajar 25-35 %.
A17: planta_QS | B17: Quillay (Quillaja saponaria), Bolsa 20x30, 1,0-1,3 m | C17: u | D17: 4622 | E17: 6723 | F17: 10504 | G17: Precio vivero al detalle convertido a neto; compras por volumen pueden bajar 25-35 %.
A18: planta_CD | B18: Carbonillo (Cordia decandra), Bolsa 20x30, 1,0-1,3 m | C18: u | D18: 4202 | E18: 6723 | F18: 12605 | G18: Precio vivero al detalle convertido a neto; compras por volumen pueden bajar 25-35 %.
A19: planta_SP | B19: Huingán (Schinus polygamus), Bolsa 20x30, 1,0-1,3 m | C19: u | D19: 5042 | E19: 6723 | F19: 9244 | G19: Precio vivero al detalle convertido a neto; compras por volumen pueden bajar 25-35 %.
A20: planta_PC | B20: Guayacán (Porlieria chilensis), Bolsa 20x30, 1,0-1,3 m | C20: u | D20: 11765 | E20: 15126 | F20: 25210 | G20: Precio vivero al detalle convertido a neto; compras por volumen pueden bajar 25-35 %.
A21: planta_HS | B21: Palo negro (Heliotropium stenophyllum), Bolsa 15x20 | C21: u | D21: 1639 | E21: 2521 | F21: 3782 | G21: Precio vivero al detalle convertido a neto; compras por volumen pueden bajar 25-35 %.
A22: planta_BA | B22: Chamiza (Bahia ambrosioides), Bolsa 15x20 | C22: u | D22: 1475 | E22: 2269 | F22: 3025 | G22: Precio vivero al detalle convertido a neto; compras por volumen pueden bajar 25-35 %.
A23: planta_FT | B23: Maravilla del campo (Flourensia thurifera), Bolsa 15x20 | C23: u | D23: 1529 | E23: 2353 | F23: 3361 | G23: Precio vivero al detalle convertido a neto; compras por volumen pueden bajar 25-35 %.
A24: planta_SC | B24: Quebracho del norte (Senna cumingii var. coquimbensis), Bolsa 15x20 | C24: u | D24: 1912 | E24: 2941 | F24: 4202 | G24: Precio vivero al detalle convertido a neto; compras por volumen pueden bajar 25-35 %.
A25: planta_FL | B25: Palo de yegua (Fuchsia lycioides), Bolsa 15x20 | C25: u | D25: 1639 | E25: 2521 | F25: 3361 | G25: Precio vivero al detalle convertido a neto; compras por volumen pueden bajar 25-35 %.
A26: planta_EC | B26: Coronilla del fraile (Encelia canescens), Bolsa 15x20 | C26: u | D26: 1336 | E26: 2101 | F26: 2941 | G26: Precio vivero al detalle convertido a neto; compras por volumen pueden bajar 25-35 %.
A27: planta_BP | B27: Amancay / Copa de oro (Balbisia peduncularis), Bolsa 15x20 | C27: u | D27: 1639 | E27: 2521 | F27: 4202 | G27: Precio vivero al detalle convertido a neto; compras por volumen pueden bajar 25-35 %.
... A39: gravilla_m3 | B39: Gravilla natural 10-20 mm puesta en obra en Tongoy (suministro + flete) | C39: m³ | D39: 27000 | E39: 36000 | F39: 50000 | G39: Planta La Serena ~$18-28 mil/m3 + flete ~50 km a Tongoy
A40: mo_gravilla_m2 | B40: Extendido y nivelación de gravilla e=10 cm | C40: m² | D40: 1000 | E40: 1300 | F40: 2200
A41: diseno_riego | B41: Diseño y cálculo hidráulico de detalle | C41: gl | D41: 300000 | E41: 650000 | F41: 1200000
A42: gotero | B42: Gotero autocompensado antidrenante 2 L/h | C42: u | D42: 151 | E42: 294 | F42: 546
A43: pe16_m | B43: Tubería PE 16 mm UV | C43: m | D43: 101 | E43: 168 | F43: 269
A44: fittings_pe | B44: Fittings PE 16 mm (juego completo) | C44: gl | D44: 168067 | E44: 268908 | F44: 436975
A45: pvc32_m | B45: Tubería PVC 32 mm C10 + prorrata de fittings | C45: m | D45: 1078 | E45: 1454 | F45: 1924
A46: zanja_m | B46: Zanja, cama de arena, instalación y tapado de matriz | C46: m | D46: 2500 | E46: 4000 | F46: 6500
A47: valvula | B47: Válvula solenoide 1" + solenoide latch 9V | C47: u | D47: 36974 | E47: 56303 | F47: 84033
A48: programador | B48: Programador a batería 4 estaciones | C48: u | D48: 134454 | E48: 218487 | F48: 336134
A49: cabezal | B49: Cabezal: conexión/antirretorno, llave 1", filtro anillas, regulador, remarcador, acople rápido | C49: gl | D49: 109874 | E49: 198782 | F49: 335546
A50: camara | B50: Cámara de válvulas registrable | C50: u | D50: 18487 | E50: 37815 | F50: 58824
A51: mo_riego_gotero | B51: Mano de obra instalación de riego por gotero instalado | C51: gotero | D51: 400 | E51: 650 | F51: 1100
A52: mo_cabezal_pruebas | B52: Armado de cabezal y manifold, lavado, pruebas, programación | C52: gl | D52: 150000 | E52: 250000 | F52: 400000 | G52: Estimación con jornadas de maestro gasfíter/riego
...

Sheet Comparables
A1: Triangulación con precios de mercado por m² (no usa el Manual COPEC)
A3: Referencia | B3: Bajo | C3: Típico | D3: Alto | E3: Unidad | F3: IVA | G3: Confianza | H3: Notas / fuente
A4: MINVU DS27 Región de Coquimbo 2025 - plantación de arbusto (hoyo 40x40x40), precio total | B4: 21370 | C4: 21917 | D4: 25678 | E4: CLP/u | F4: desconocido | G4: media | H4: Tabla oficial de precios referenciales (incluye planta y materiales). https://www.minvu.gob.cl/wp-content/uploads/2025/10/ - Zona 1 a Zona 4
A5: MINVU DS27 Región de Coquimbo 2025 - plantación de cubresuelo, precio total | B5: 8517 | C5: 9400 | D5: 9979 | E5: CLP/u | F5: desconocido | G5: media | H5: Ídem
A6: Subcontrato jardín xerófito / bajo consumo hídrico (suministro + instalación) | B6: 22000 | C6: 33000 | D6: 58000 | E6: CLP/m2 | F6: neto | G6: baja | H6: Rango de licitaciones y cotizaciones reportado por la investigación (sin URL única)
A7: Subcontrato sistema de riego por goteo completo | B7: 3500 | C7: 6000 | D7: 12000 | E7: CLP/m2 | F7: neto | G7: baja | H7: Ídem
A8: Subcontrato suministro e instalación de gravilla e=10 cm | B8: 7500 | C8: 10500 | D8: 18000 | E8: CLP/m2 | F8: neto | G8: baja | H8: Ídem
A9: Planta nativa por volumen (mayorista, bolsa 13x16) | B9: 1000 | C9: 1200 | D9: 1600 | E9: CLP/u | F9: neto | G9: media | H9: Nodriza SpA tabla stock 2025 https://nodrizaspa.cl/inicio-e-commerce/

Sheet Fuentes
A1: Fuentes de precios consultadas (extractos web, oct-2026)
A3: Clave | B3: Fuente | C3: URL | D3: Precio publicado (CLP) | E3: Nota
A4: compost_m3 | B4: verificación | C4: https://nodrizaspa.cl/inicio-e-commerce/ | D4: 2000 | E4: Nodriza, tabla 'stock disponible 2025', valores NETOS (+IVA). Formato 13x16 (unos 0,9-1 L): $1.500-2.000 al detalle y $1.000-1.200 mayorista según la especie (chagual, coirón, huilmo, chilco). Extracto de WebSearch obtenido en esta sesión por otro agente; no pude abrir la página.
A5: compost_m3 | B5: verificación | C5: https://www.raizlocal.cl/shop/cha-amb-b18x18-chamiza-b18x18-554 | D5: 2900 | E5: Raíz Local, chamiza (Bahia ambrosioides) en bolsa 18x18 (unos 2 L), 0,5-1 m. La página no indica si incluye IVA. Despacho a regiones con compra mínima de $100.000. Extracto de WebSearch.
A6: compost_m3 | B6: verificación | C6: https://nodrizaspa.cl/producto/chamiza-bahia-ambrosioides-2/ | D6: 2975 | E6: Nodriza, chamiza, $2.975 con IVA incluido (unos $2.500 netos). Extracto de WebSearch.
A7: compost_m3 | B7: verificación | C7: https://viveroloschungungos.cl/tienda/ | D7: 4000 | E7: Viveros Los Chungungos, palo de yegua (Fuchsia lycioides) en bolsa 25x30 cm (unos 6 L): $4.000 en oferta, $5.950 normal. No dice si incluye IVA. Extracto de WebSearch.
A8: tutor | B8: Vivero Las Brujas - Tutor pino impregnado 2,40 m | C8: https://viverolasbrujas.cl/producto/tutor-de-pino-impregnado-2-40m/ | D8: 2300 | E8: Página de unos 480 días
A9: tutor | B9: Lifewood - Polín pino impregnado 2" a 3" x 2,44 m | C9: https://lifewood.cl/products/rodrigon-de-pino-impregnado-de-2-a-3-x-2-44-mts | D9: 3670 | E9: Impuesto incluido
A10: tutor | B10: Masmadera - Polín impregnado 2-3" x 2,44 m | C10: https://masmadera.cl/en/collections/polines-impregnados | D10: 3056 | E10: IVA no explícito
A11: tutor | B11: Sodimac - Polín impregnado 3" a 4" x 2,44 m | C11: https://www.sodimac.cl/sodimac-cl/product/75577X/3''-a-4''-75-a-100-mm-x-2.44-m-Polin-impregnado | D11: 3890 | E11: Otras capturas muestran $4.740-4.990. Precio mayorista sobre 40 unidades: $4.937. Impregnado CCA
A12: tutor | B12: Mercado Libre - Tutor colihue 2,0 m (paquete de 15) | C12: https://listado.mercadolibre.cl/tutores-de-coligue | D12: 993 | E12: $14.900 el paquete de 15, unos $993 por unidad
A13: tutor | B13: La Mano Verde - Amarra profesional reutilizable de goma 21 cm | C13: https://www.lamanoverde.cl/categoria-producto/accesorios-y-herramientas/tutores-y-amarras/ | D13: 300 | E13: Precio por unidad
A14: planta_SL | B14: Vivero Cultiva (Pirque) - Molle 60-99 cm | C14: https://www.viverocultiva.cl/products/molle-schinus-latifolius-0-30-a-0-60 | D14: 4990 | E14: Variantes: 15-29 cm $1.600, 30-59 cm $2.990, 60-99 cm $4.990. Venta con boleta (IVA incluido). Más de 100 unidades o con factura: vivero@cultiva.cl
A15: planta_SL | B15: Vivero Los Chungungos (Puchuncaví) - Molle pelado bolsa 20x40 | C15: https://viveroloschungungos.cl/tienda/ | D15: 6000 | E15: $6.000 en oferta ($10.000 normal). Altura no indicada en el extracto. Molle peludo 12x25: $1.800 (oferta)
... A141: mant_m2_mes | B141: Jornada de jardinero, Región de Coquimbo (de memoria) | C141: n/d | D141: 40000 | E141: Valor por jornada usado para calcular el costo por visita en un jardín pequeño. Sin verificar.
